<?xml version="1.0" encoding="utf-8"?>
<!-- This URDF was automatically created by SolidWorks to URDF Exporter! Originally created by Stephen Brawner (brawner@gmail.com) 
     Commit Version: 1.5.1-0-g916b5db  Build Version: 1.5.7152.31018
     For more information, please see http://wiki.ros.org/sw_urdf_exporter -->
<robot
  name="robotarm">
  <link
    name="base_link">
    <inertial>
      <origin
        xyz="0 7.73940626185152E-18 0.0943086092715232"
        rpy="0 0 0" />
      <mass
        value="5.6925658883047" />
      <inertia
        ixx="0.0253978911460265"
        ixy="-5.19141599830795E-51"
        ixz="-8.47850573713574E-35"
        iyy="0.0253978911460265"
        iyz="5.84007442267779E-20"
        izz="0.0263516791783112" />
    </inertial>
    <visual>
      <origin
        xyz="0 0 0"
        rpy="0 0 0" />
      <geometry>
        <mesh
          filename="package://robotarm/meshes/base_link.STL" />
      </geometry>
      <material
        name="">
        <color
          rgba="0.792156862745098 0.819607843137255 0.933333333333333 1" />
      </material>
    </visual>
    <collision>
      <origin
        xyz="0 0 0"
        rpy="0 0 0" />
      <geometry>
        <mesh
          filename="package://robotarm/meshes/base_link.STL" />
      </geometry>
    </collision>
  </link>
  <link
    name="Link_1">
    <inertial>
      <origin
        xyz="0.0994051462871013 0.0499999999560493 1.61421868932957E-08"
        rpy="0 0 0" />
      <mass
        value="0.968515917956123" />
      <inertia
        ixx="0.00101098741855169"
        ixy="-4.24067273865609E-12"
        ixz="8.95948128514241E-11"
        iyy="0.00130687061897204"
        iyz="3.92629041664754E-10"
        izz="0.00125061992464247" />
    </inertial>
    <visual>
      <origin
        xyz="0 0 0"
        rpy="0 0 0" />
      <geometry>
        <mesh
          filename="package://robotarm/meshes/Link_1.STL" />
      </geometry>
      <material
        name="">
        <color
          rgba="0.792156862745098 0.819607843137255 0.933333333333333 1" />
      </material>
    </visual>
    <collision>
      <origin
        xyz="0 0 0"
        rpy="0 0 0" />
      <geometry>
        <mesh
          filename="package://robotarm/meshes/Link_1.STL" />
      </geometry>
    </collision>
  </link>
  <joint
    name="Joint_1"
    type="continuous">
    <origin
      xyz="0 0 0.1652"
      rpy="1.5707963267949 0 0" />
    <parent
      link="base_link" />
    <child
      link="Link_1" />
    <axis
      xyz="0 1 0" />
  </joint>
  <link
    name="Link_2">
    <inertial>
      <origin
        xyz="0.0499999836856851 0.1755 2.64244421609409E-07"
        rpy="0 0 0" />
      <mass
        value="1.28853409511538" />
      <inertia
        ixx="0.022686909508374"
        ixy="5.64445715793553E-19"
        ixz="3.22100359901118E-09"
        iyy="0.00137829240474618"
        iyz="-3.00514315005634E-19"
        izz="0.0225743861223479" />
    </inertial>
    <visual>
      <origin
        xyz="0 0 0"
        rpy="0 0 0" />
      <geometry>
        <mesh
          filename="package://robotarm/meshes/Link_2.STL" />
      </geometry>
      <material
        name="">
        <color
          rgba="0.792156862745098 0.819607843137255 0.933333333333333 1" />
      </material>
    </visual>
    <collision>
      <origin
        xyz="0 0 0"
        rpy="0 0 0" />
      <geometry>
        <mesh
          filename="package://robotarm/meshes/Link_2.STL" />
      </geometry>
    </collision>
  </link>
  <joint
    name="Joint_2"
    type="continuous">
    <origin
      xyz="0.112400000000005 0.0500000000000001 0"
      rpy="0 0 0" />
    <parent
      link="Link_1" />
    <child
      link="Link_2" />
    <axis
      xyz="1 0 0" />
  </joint>
  <link
    name="Link_3">
    <inertial>
      <origin
        xyz="-0.0312000000000064 -1.11022302462516E-16 1.71845661893685E-18"
        rpy="0 0 0" />
      <mass
        value="1.18174149257434" />
      <inertia
        ixx="0.000883642048860509"
        ixy="-1.45583746962657E-35"
        ixz="2.82850736616679E-36"
        iyy="0.00796527652302551"
        iyz="3.26265223399926E-52"
        izz="0.00796527652302551" />
    </inertial>
    <visual>
      <origin
        xyz="0 0 0"
        rpy="0 0 0" />
      <geometry>
        <mesh
          filename="package://robotarm/meshes/Link_3.STL" />
      </geometry>
      <material
        name="">
        <color
          rgba="0.792156862745098 0.819607843137255 0.933333333333333 1" />
      </material>
    </visual>
    <collision>
      <origin
        xyz="0 0 0"
        rpy="0 0 0" />
      <geometry>
        <mesh
          filename="package://robotarm/meshes/Link_3.STL" />
      </geometry>
    </collision>
  </link>
  <joint
    name="Joint_3"
    type="continuous">
    <origin
      xyz="0 0.351 0"
      rpy="0 0 0" />
    <parent
      link="Link_2" />
    <child
      link="Link_3" />
    <axis
      xyz="1 0 0" />
  </joint>
  <link
    name="Link_4">
    <inertial>
      <origin
        xyz="-0.0499999884862342 0.175600002581584 2.25121599863398E-07"
        rpy="0 0 0" />
      <mass
        value="1.28909961850142" />
      <inertia
        ixx="0.0227161468686484"
        ixy="6.51842272813438E-10"
        ixz="-3.22480744280282E-09"
        iyy="0.00137854681548726"
        iyz="5.50711970014189E-09"
        izz="0.022603623568969" />
    </inertial>
    <visual>
      <origin
        xyz="0 0 0"
        rpy="0 0 0" />
      <geometry>
        <mesh
          filename="package://robotarm/meshes/Link_4.STL" />
      </geometry>
      <material
        name="">
        <color
          rgba="0.792156862745098 0.819607843137255 0.933333333333333 1" />
      </material>
    </visual>
    <collision>
      <origin
        xyz="0 0 0"
        rpy="0 0 0" />
      <geometry>
        <mesh
          filename="package://robotarm/meshes/Link_4.STL" />
      </geometry>
    </collision>
  </link>
  <joint
    name="Joint_4"
    type="continuous">
    <origin
      xyz="-0.0624000000000001 0 0"
      rpy="0 0 0" />
    <parent
      link="Link_3" />
    <child
      link="Link_4" />
    <axis
      xyz="1 0 0" />
  </joint>
  <link
    name="Link_5">
    <inertial>
      <origin
        xyz="0.0234778306347505 9.19930254195123E-09 9.67011043676775E-08"
        rpy="0 0 0" />
      <mass
        value="1.20648390273837" />
      <inertia
        ixx="0.00141049786190329"
        ixy="-4.78535096297326E-12"
        ixz="-1.50596997323671E-10"
        iyy="0.00750318533563848"
        iyz="-2.22975998606996E-10"
        izz="0.00738627403646385" />
    </inertial>
    <visual>
      <origin
        xyz="0 0 0"
        rpy="0 0 0" />
      <geometry>
        <mesh
          filename="package://robotarm/meshes/Link_5.STL" />
      </geometry>
      <material
        name="">
        <color
          rgba="0.792156862745098 0.819607843137255 0.933333333333333 1" />
      </material>
    </visual>
    <collision>
      <origin
        xyz="0 0 0"
        rpy="0 0 0" />
      <geometry>
        <mesh
          filename="package://robotarm/meshes/Link_5.STL" />
      </geometry>
    </collision>
  </link>
  <joint
    name="Joint_5"
    type="continuous">
    <origin
      xyz="0 0.3512 0"
      rpy="0 0 0" />
    <parent
      link="Link_4" />
    <child
      link="Link_5" />
    <axis
      xyz="1 0 0" />
  </joint>
  <link
    name="Link_6">
    <inertial>
      <origin
        xyz="-4.94980857412841E-08 0.0422699130962683 -6.31668961434475E-08"
        rpy="0 0 0" />
      <mass
        value="0.869909136744433" />
      <inertia
        ixx="0.00355831006646369"
        ixy="-3.18908705115779E-12"
        ixz="2.62810393495205E-10"
        iyy="0.0010013970608803"
        iyz="1.20370999840181E-10"
        izz="0.0034916422873186" />
    </inertial>
    <visual>
      <origin
        xyz="0 0 0"
        rpy="0 0 0" />
      <geometry>
        <mesh
          filename="package://robotarm/meshes/Link_6.STL" />
      </geometry>
      <material
        name="">
        <color
          rgba="0.792156862745098 0.819607843137255 0.933333333333333 1" />
      </material>
    </visual>
    <collision>
      <origin
        xyz="0 0 0"
        rpy="0 0 0" />
      <geometry>
        <mesh
          filename="package://robotarm/meshes/Link_6.STL" />
      </geometry>
    </collision>
  </link>
  <joint
    name="Joint_6"
    type="continuous">
    <origin
      xyz="0.112399999999994 0 0"
      rpy="0 0 0" />
    <parent
      link="Link_5" />
    <child
      link="Link_6" />
    <axis
      xyz="0 1 0" />
  </joint>
  <link
    name="Link_7">
    <inertial>
      <origin
        xyz="0.000716983753219325 -1.01796651330588E-07 -1.01850552781586E-07"
        rpy="0 0 0" />
      <mass
        value="0.509050484778038" />
      <inertia
        ixx="0.00040231983837769"
        ixy="-1.03019225258575E-20"
        ixz="1.89129207008021E-21"
        iyy="0.000620169449706831"
        iyz="-3.47468819554008E-21"
        izz="0.000620258735109744" />
    </inertial>
    <visual>
      <origin
        xyz="0 0 0"
        rpy="0 0 0" />
      <geometry>
        <mesh
          filename="package://robotarm/meshes/Link_7.STL" />
      </geometry>
      <material
        name="">
        <color
          rgba="0.792156862745098 0.819607843137255 0.933333333333333 1" />
      </material>
    </visual>
    <collision>
      <origin
        xyz="0 0 0"
        rpy="0 0 0" />
      <geometry>
        <mesh
          filename="package://robotarm/meshes/Link_7.STL" />
      </geometry>
    </collision>
  </link>
  <joint
    name="Joint_7"
    type="continuous">
    <origin
      xyz="0 0.112399999999999 0"
      rpy="0 0 0" />
    <parent
      link="Link_6" />
    <child
      link="Link_7" />
    <axis
      xyz="1 0 0" />
  </joint>
  <link
    name="Catcher_Upper">
    <inertial>
      <origin
        xyz="0.0103562597406325 -4.16601547991608E-15 0.0846074139278834"
        rpy="0 0 0" />
      <mass
        value="0.416502433291861" />
      <inertia
        ixx="0.00151418519618709"
        ixy="4.50333127528385E-19"
        ixz="-0.000112588737198718"
        iyy="0.000642490517610021"
        iyz="2.36068207601853E-18"
        izz="0.00113999849514466" />
    </inertial>
    <visual>
      <origin
        xyz="0 0 0"
        rpy="0 0 0" />
      <geometry>
        <mesh
          filename="package://robotarm/meshes/Catcher_Upper.STL" />
      </geometry>
      <material
        name="">
        <color
          rgba="0.792156862745098 0.819607843137255 0.933333333333333 1" />
      </material>
    </visual>
    <collision>
      <origin
        xyz="0 0 0"
        rpy="0 0 0" />
      <geometry>
        <mesh
          filename="package://robotarm/meshes/Catcher_Upper.STL" />
      </geometry>
    </collision>
  </link>
  <joint
    name="Catcher_Joint_Upper"
    type="continuous">
    <origin
      xyz="0.0600000000000074 0.00750000000000006 0"
      rpy="-1.57079632679487 0 0" />
    <parent
      link="Link_7" />
    <child
      link="Catcher_Upper" />
    <axis
      xyz="0 1 0" />
  </joint>
  <link
    name="Catcher_Lower">
    <inertial>
      <origin
        xyz="0.0105679344924045 -1.85281486576348E-05 0.086092141977225"
        rpy="0 0 0" />
      <mass
        value="0.408159928023487" />
      <inertia
        ixx="0.00146549427330268"
        ixy="-7.93342266222431E-19"
        ixz="-0.000106184500270765"
        iyy="0.000596328759685478"
        iyz="1.41189184907675E-18"
        izz="0.00113535939960049" />
    </inertial>
    <visual>
      <origin
        xyz="0 0 0"
        rpy="0 0 0" />
      <geometry>
        <mesh
          filename="package://robotarm/meshes/Catcher_Lower.STL" />
      </geometry>
      <material
        name="">
        <color
          rgba="0.792156862745098 0.819607843137255 0.933333333333333 1" />
      </material>
    </visual>
    <collision>
      <origin
        xyz="0 0 0"
        rpy="0 0 0" />
      <geometry>
        <mesh
          filename="package://robotarm/meshes/Catcher_Lower.STL" />
      </geometry>
    </collision>
  </link>
  <joint
    name="Catcher_Joint_Lower"
    type="continuous">
    <origin
      xyz="0.0600000000000073 -0.00750000000000006 0"
      rpy="1.57079632679492 0 0" />
    <parent
      link="Link_7" />
    <child
      link="Catcher_Lower" />
    <axis
      xyz="0 1 0" />
  </joint>
</robot>