<?xml version="1.0" encoding="utf-8"?>
<!-- This URDF was automatically created by SolidWorks to URDF Exporter! Originally created by Stephen Brawner (brawner@gmail.com) 
     Commit Version: 1.5.1-0-g916b5db  Build Version: 1.5.7152.31018
     For more information, please see http://wiki.ros.org/sw_urdf_exporter -->
<robot
  name="robotarm">
  <link
    name="link1">
    <inertial>
      <origin
        xyz="0 7.7394E-18 0.094309"
        rpy="0 0 0" />
      <mass
        value="5.6926" />
      <inertia
        ixx="0.025398"
        ixy="-5.1914E-51"
        ixz="-8.4785E-35"
        iyy="0.025398"
        iyz="5.8401E-20"
        izz="0.026352" />
    </inertial>
    <visual>
      <origin
        xyz="0 0 0"
        rpy="0 0 0" />
      <geometry>
        <mesh
          filename="package://robotarm/meshes/link1.STL" />
      </geometry>
      <material
        name="">
        <color
          rgba="0.79216 0.81961 0.93333 1" />
      </material>
    </visual>
    <collision>
      <origin
        xyz="0 0 0"
        rpy="0 0 0" />
      <geometry>
        <mesh
          filename="package://robotarm/meshes/link1.STL" />
      </geometry>
    </collision>
  </link>
  <link
    name="link2">
    <inertial>
      <origin
        xyz="0.099405 -4.3951E-11 1.6142E-08"
        rpy="0 0 0" />
      <mass
        value="0.96852" />
      <inertia
        ixx="0.001011"
        ixy="-4.2407E-12"
        ixz="8.9595E-11"
        iyy="0.0013069"
        iyz="3.9263E-10"
        izz="0.0012506" />
    </inertial>
    <visual>
      <origin
        xyz="0 0 0"
        rpy="0 0 0" />
      <geometry>
        <mesh
          filename="package://robotarm/meshes/link2.STL" />
      </geometry>
      <material
        name="">
        <color
          rgba="0.79216 0.81961 0.93333 1" />
      </material>
    </visual>
    <collision>
      <origin
        xyz="0 0 0"
        rpy="0 0 0" />
      <geometry>
        <mesh
          filename="package://robotarm/meshes/link2.STL" />
      </geometry>
    </collision>
  </link>
  <joint
    name="joint1to2"
    type="continuous">
    <origin
      xyz="0 0 0.2152"
      rpy="1.5708 0 0" />
    <parent
      link="link1" />
    <child
      link="link2" />
    <axis
      xyz="0 1 0" />
  </joint>
  <link
    name="link3">
    <inertial>
      <origin
        xyz="-1.6314E-08 0.1755 2.6424E-07"
        rpy="0 0 0" />
      <mass
        value="1.2885" />
      <inertia
        ixx="0.022687"
        ixy="5.6445E-19"
        ixz="3.221E-09"
        iyy="0.0013783"
        iyz="-3.0051E-19"
        izz="0.022574" />
    </inertial>
    <visual>
      <origin
        xyz="0 0 0"
        rpy="0 0 0" />
      <geometry>
        <mesh
          filename="package://robotarm/meshes/link3.STL" />
      </geometry>
      <material
        name="">
        <color
          rgba="0.79216 0.81961 0.93333 1" />
      </material>
    </visual>
    <collision>
      <origin
        xyz="0 0 0"
        rpy="0 0 0" />
      <geometry>
        <mesh
          filename="package://robotarm/meshes/link3.STL" />
      </geometry>
    </collision>
  </link>
  <joint
    name="joint2to3"
    type="continuous">
    <origin
      xyz="0.1624 0 0"
      rpy="0 0 0" />
    <parent
      link="link2" />
    <child
      link="link3" />
    <axis
      xyz="1 0 0" />
  </joint>
  <link
    name="link4">
    <inertial>
      <origin
        xyz="-0.0812 -1.1102E-16 1.7185E-18"
        rpy="0 0 0" />
      <mass
        value="1.1817" />
      <inertia
        ixx="0.00088364"
        ixy="-1.4558E-35"
        ixz="2.8285E-36"
        iyy="0.0079653"
        iyz="3.2627E-52"
        izz="0.0079653" />
    </inertial>
    <visual>
      <origin
        xyz="0 0 0"
        rpy="0 0 0" />
      <geometry>
        <mesh
          filename="package://robotarm/meshes/link4.STL" />
      </geometry>
      <material
        name="">
        <color
          rgba="0.79216 0.81961 0.93333 1" />
      </material>
    </visual>
    <collision>
      <origin
        xyz="0 0 0"
        rpy="0 0 0" />
      <geometry>
        <mesh
          filename="package://robotarm/meshes/link4.STL" />
      </geometry>
    </collision>
  </link>
  <joint
    name="joint3to4"
    type="continuous">
    <origin
      xyz="0 0.351 0"
      rpy="0 0 0" />
    <parent
      link="link3" />
    <child
      link="link4" />
    <axis
      xyz="1 0 0" />
  </joint>
  <link
    name="link5">
    <inertial>
      <origin
        xyz="1.1514E-08 -0.1756 2.2512E-07"
        rpy="0 0 0" />
      <mass
        value="1.2891" />
      <inertia
        ixx="0.022716"
        ixy="6.5184E-10"
        ixz="-3.2248E-09"
        iyy="0.0013785"
        iyz="5.5071E-09"
        izz="0.022604" />
    </inertial>
    <visual>
      <origin
        xyz="0 0 0"
        rpy="0 0 0" />
      <geometry>
        <mesh
          filename="package://robotarm/meshes/link5.STL" />
      </geometry>
      <material
        name="">
        <color
          rgba="0.79216 0.81961 0.93333 1" />
      </material>
    </visual>
    <collision>
      <origin
        xyz="0 0 0"
        rpy="0 0 0" />
      <geometry>
        <mesh
          filename="package://robotarm/meshes/link5.STL" />
      </geometry>
    </collision>
  </link>
  <joint
    name="joint4to5"
    type="fixed">
    <origin
      xyz="-0.1624 0.3512 0"
      rpy="0 0 0" />
    <parent
      link="link4" />
    <child
      link="link5" />
    <axis
      xyz="0 0 0" />
  </joint>
  <link
    name="link6">
    <inertial>
      <origin
        xyz="-0.088922 9.1993E-09 9.6701E-08"
        rpy="0 0 0" />
      <mass
        value="1.2065" />
      <inertia
        ixx="0.0014105"
        ixy="-4.7854E-12"
        ixz="-1.506E-10"
        iyy="0.0075032"
        iyz="-2.2298E-10"
        izz="0.0073863" />
    </inertial>
    <visual>
      <origin
        xyz="0 0 0"
        rpy="0 0 0" />
      <geometry>
        <mesh
          filename="package://robotarm/meshes/link6.STL" />
      </geometry>
      <material
        name="">
        <color
          rgba="0.79216 0.81961 0.93333 1" />
      </material>
    </visual>
    <collision>
      <origin
        xyz="0 0 0"
        rpy="0 0 0" />
      <geometry>
        <mesh
          filename="package://robotarm/meshes/link6.STL" />
      </geometry>
    </collision>
  </link>
  <joint
    name="joint5to6"
    type="continuous">
    <origin
      xyz="0.1624 0 0"
      rpy="0 0 0" />
    <parent
      link="link5" />
    <child
      link="link6" />
    <axis
      xyz="1 0 0" />
  </joint>
  <link
    name="link7">
    <inertial>
      <origin
        xyz="-4.9498E-08 -0.07013 -6.3167E-08"
        rpy="0 0 0" />
      <mass
        value="0.86991" />
      <inertia
        ixx="0.0035583"
        ixy="-3.1891E-12"
        ixz="2.6281E-10"
        iyy="0.0010014"
        iyz="1.2037E-10"
        izz="0.0034916" />
    </inertial>
    <visual>
      <origin
        xyz="0 0 0"
        rpy="0 0 0" />
      <geometry>
        <mesh
          filename="package://robotarm/meshes/link7.STL" />
      </geometry>
      <material
        name="">
        <color
          rgba="0.79216 0.81961 0.93333 1" />
      </material>
    </visual>
    <collision>
      <origin
        xyz="0 0 0"
        rpy="0 0 0" />
      <geometry>
        <mesh
          filename="package://robotarm/meshes/link7.STL" />
      </geometry>
    </collision>
  </link>
  <joint
    name="joint6to7"
    type="continuous">
    <origin
      xyz="0 0.1124 0"
      rpy="0 0 0" />
    <parent
      link="link6" />
    <child
      link="link7" />
    <axis
      xyz="0 1 0" />
  </joint>
  <link
    name="link8">
    <inertial>
      <origin
        xyz="0.00071666 4.4409E-16 -1.3163E-14"
        rpy="0 0 0" />
      <mass
        value="0.50905" />
      <inertia
        ixx="0.00040232"
        ixy="-9.8684E-21"
        ixz="-5.5284E-22"
        iyy="0.00062017"
        iyz="1.2763E-21"
        izz="0.00062026" />
    </inertial>
    <visual>
      <origin
        xyz="0 0 0"
        rpy="0 0 0" />
      <geometry>
        <mesh
          filename="package://robotarm/meshes/link8.STL" />
      </geometry>
      <material
        name="">
        <color
          rgba="0.79216 0.81961 0.93333 1" />
      </material>
    </visual>
    <collision>
      <origin
        xyz="0 0 0"
        rpy="0 0 0" />
      <geometry>
        <mesh
          filename="package://robotarm/meshes/link8.STL" />
      </geometry>
    </collision>
  </link>
  <joint
    name="joint7to8"
    type="continuous">
    <origin
      xyz="0 0 0"
      rpy="0 0 0" />
    <parent
      link="link7" />
    <child
      link="link8" />
    <axis
      xyz="1 0 0" />
  </joint>
  <link
    name="catcher_upper">
    <inertial>
      <origin
        xyz="0.05561 -1.269E-06 -0.0087028"
        rpy="0 0 0" />
      <mass
        value="0.072139" />
      <inertia
        ixx="4.0156E-05"
        ixy="6.8408E-10"
        ixz="2.6031E-05"
        iyy="0.00011549"
        iyz="-1.0917E-10"
        izz="0.00012128" />
    </inertial>
    <visual>
      <origin
        xyz="0 0 0"
        rpy="0 0 0" />
      <geometry>
        <mesh
          filename="package://robotarm/meshes/catcher_upper.STL" />
      </geometry>
      <material
        name="">
        <color
          rgba="0.79216 0.81961 0.93333 1" />
      </material>
    </visual>
    <collision>
      <origin
        xyz="0 0 0"
        rpy="0 0 0" />
      <geometry>
        <mesh
          filename="package://robotarm/meshes/catcher_upper.STL" />
      </geometry>
    </collision>
  </link>
  <joint
    name="joint_upper"
    type="continuous">
    <origin
      xyz="0.06 0.0075 0"
      rpy="-1.5708 0 0.58786" />
    <parent
      link="link8" />
    <child
      link="catcher_upper" />
    <axis
      xyz="0 1 0" />
  </joint>
  <link
    name="catcher_lower">
    <inertial>
      <origin
        xyz="0.058052 -1.3085E-14 -0.0091063"
        rpy="0 0 0" />
      <mass
        value="0.034473" />
      <inertia
        ixx="9.3068E-06"
        ixy="3.1301E-21"
        ixz="1.225E-05"
        iyy="5.2903E-05"
        iyz="-6.9958E-22"
        izz="4.5347E-05" />
    </inertial>
    <visual>
      <origin
        xyz="0 0 0"
        rpy="0 0 0" />
      <geometry>
        <mesh
          filename="package://robotarm/meshes/catcher_lower.STL" />
      </geometry>
      <material
        name="">
        <color
          rgba="0.79216 0.81961 0.93333 1" />
      </material>
    </visual>
    <collision>
      <origin
        xyz="0 0 0"
        rpy="0 0 0" />
      <geometry>
        <mesh
          filename="package://robotarm/meshes/catcher_lower.STL" />
      </geometry>
    </collision>
  </link>
  <joint
    name="joint_lower"
    type="continuous">
    <origin
      xyz="0.06 -0.0075 0"
      rpy="1.5708 0 -0.60211" />
    <parent
      link="link8" />
    <child
      link="catcher_lower" />
    <axis
      xyz="0 1 0" />
  </joint>
</robot>