<?xml version="1.0" encoding="utf-8"?>
<!-- This URDF was automatically created by SolidWorks to URDF Exporter! Originally created by Stephen Brawner (brawner@gmail.com) 
     Commit Version: 1.5.1-0-g916b5db  Build Version: 1.5.7152.31018
     For more information, please see http://wiki.ros.org/sw_urdf_exporter -->
<robot
  name="robotarm">
  <link
    name="link1">
    <inertial>
      <origin
        xyz="0 7.73940626185152E-18 0.0943086092715232"
        rpy="0 0 0" />
      <mass
        value="5.6925658883047" />
      <inertia
        ixx="0.0253978911460265"
        ixy="-5.19141599830795E-51"
        ixz="-8.47850573713574E-35"
        iyy="0.0253978911460265"
        iyz="5.84007442267779E-20"
        izz="0.0263516791783112" />
    </inertial>
    <visual>
      <origin
        xyz="0 0 0"
        rpy="0 0 0" />
      <geometry>
        <mesh
          filename="package://robotarm/meshes/link1.STL" />
      </geometry>
      <material
        name="">
        <color
          rgba="0.792156862745098 0.819607843137255 0.933333333333333 1" />
      </material>
    </visual>
    <collision>
      <origin
        xyz="0 0 0"
        rpy="0 0 0" />
      <geometry>
        <mesh
          filename="package://robotarm/meshes/link1.STL" />
      </geometry>
    </collision>
  </link>
  <link
    name="link2">
    <inertial>
      <origin
        xyz="0.0994051462871014 -4.39507041871678E-11 1.61421868932957E-08"
        rpy="0 0 0" />
      <mass
        value="0.968515917956123" />
      <inertia
        ixx="0.00101098741855169"
        ixy="-4.24067273865609E-12"
        ixz="8.95948128514241E-11"
        iyy="0.00130687061897204"
        iyz="3.92629041664754E-10"
        izz="0.00125061992464247" />
    </inertial>
    <visual>
      <origin
        xyz="0 0 0"
        rpy="0 0 0" />
      <geometry>
        <mesh
          filename="package://robotarm/meshes/link2.STL" />
      </geometry>
      <material
        name="">
        <color
          rgba="0.792156862745098 0.819607843137255 0.933333333333333 1" />
      </material>
    </visual>
    <collision>
      <origin
        xyz="0 0 0"
        rpy="0 0 0" />
      <geometry>
        <mesh
          filename="package://robotarm/meshes/link2.STL" />
      </geometry>
    </collision>
  </link>
  <joint
    name="joint1to2"
    type="continuous">
    <origin
      xyz="0 0 0.2152"
      rpy="1.5707963267949 0 0" />
    <parent
      link="link1" />
    <child
      link="link2" />
    <axis
      xyz="0 1 0" />
  </joint>
  <link
    name="link3">
    <inertial>
      <origin
        xyz="-1.63143103748542E-08 0.1755 2.64244421609409E-07"
        rpy="0 0 0" />
      <mass
        value="1.28853409511538" />
      <inertia
        ixx="0.022686909508374"
        ixy="5.75033630158586E-19"
        ixz="3.22100359901118E-09"
        iyy="0.00137829240474618"
        iyz="-3.00514315005634E-19"
        izz="0.0225743861223479" />
    </inertial>
    <visual>
      <origin
        xyz="0 0 0"
        rpy="0 0 0" />
      <geometry>
        <mesh
          filename="package://robotarm/meshes/link3.STL" />
      </geometry>
      <material
        name="">
        <color
          rgba="0.792156862745098 0.819607843137255 0.933333333333333 1" />
      </material>
    </visual>
    <collision>
      <origin
        xyz="0 0 0"
        rpy="0 0 0" />
      <geometry>
        <mesh
          filename="package://robotarm/meshes/link3.STL" />
      </geometry>
    </collision>
  </link>
  <joint
    name="joint2to3"
    type="continuous">
    <origin
      xyz="0.1624 0 0"
      rpy="0 0 0" />
    <parent
      link="link2" />
    <child
      link="link3" />
    <axis
      xyz="1 0 0" />
  </joint>
  <link
    name="link4">
    <inertial>
      <origin
        xyz="-0.0812000000000019 -1.11022302462516E-16 1.71845661893685E-18"
        rpy="0 0 0" />
      <mass
        value="1.18174149257434" />
      <inertia
        ixx="0.000883642048860509"
        ixy="-1.45583746962657E-35"
        ixz="-8.81620763116716E-36"
        iyy="0.00796527652302551"
        iyz="3.26265223399926E-52"
        izz="0.00796527652302551" />
    </inertial>
    <visual>
      <origin
        xyz="0 0 0"
        rpy="0 0 0" />
      <geometry>
        <mesh
          filename="package://robotarm/meshes/link4.STL" />
      </geometry>
      <material
        name="">
        <color
          rgba="0.792156862745098 0.819607843137255 0.933333333333333 1" />
      </material>
    </visual>
    <collision>
      <origin
        xyz="0 0 0"
        rpy="0 0 0" />
      <geometry>
        <mesh
          filename="package://robotarm/meshes/link4.STL" />
      </geometry>
    </collision>
  </link>
  <joint
    name="joint3to4"
    type="continuous">
    <origin
      xyz="0 0.351 0"
      rpy="0 0 0" />
    <parent
      link="link3" />
    <child
      link="link4" />
    <axis
      xyz="1 0 0" />
  </joint>
  <link
    name="link5">
    <inertial>
      <origin
        xyz="1.15137702988831E-08 -0.175599997418416 2.25121599863398E-07"
        rpy="0 0 0" />
      <mass
        value="1.28909961850142" />
      <inertia
        ixx="0.0227161468686484"
        ixy="6.51842272834614E-10"
        ixz="-3.22480744280282E-09"
        iyy="0.00137854681548726"
        iyz="5.50711970014189E-09"
        izz="0.022603623568969" />
    </inertial>
    <visual>
      <origin
        xyz="0 0 0"
        rpy="0 0 0" />
      <geometry>
        <mesh
          filename="package://robotarm/meshes/link5.STL" />
      </geometry>
      <material
        name="">
        <color
          rgba="0.792156862745098 0.819607843137255 0.933333333333333 1" />
      </material>
    </visual>
    <collision>
      <origin
        xyz="0 0 0"
        rpy="0 0 0" />
      <geometry>
        <mesh
          filename="package://robotarm/meshes/link5.STL" />
      </geometry>
    </collision>
  </link>
  <joint
    name="joint4to5"
    type="fixed">
    <origin
      xyz="-0.1624 0.3512 0"
      rpy="0 0 0" />
    <parent
      link="link4" />
    <child
      link="link5" />
    <axis
      xyz="0 0 0" />
  </joint>
  <link
    name="link6">
    <inertial>
      <origin
        xyz="-0.0889221693652386 9.19930298604044E-09 9.67011043676775E-08"
        rpy="0 0 0" />
      <mass
        value="1.20648390273837" />
      <inertia
        ixx="0.00141049786190329"
        ixy="-4.78535096297326E-12"
        ixz="-1.50596997323671E-10"
        iyy="0.00750318533563848"
        iyz="-2.22975998606996E-10"
        izz="0.00738627403646385" />
    </inertial>
    <visual>
      <origin
        xyz="0 0 0"
        rpy="0 0 0" />
      <geometry>
        <mesh
          filename="package://robotarm/meshes/link6.STL" />
      </geometry>
      <material
        name="">
        <color
          rgba="0.792156862745098 0.819607843137255 0.933333333333333 1" />
      </material>
    </visual>
    <collision>
      <origin
        xyz="0 0 0"
        rpy="0 0 0" />
      <geometry>
        <mesh
          filename="package://robotarm/meshes/link6.STL" />
      </geometry>
    </collision>
  </link>
  <joint
    name="joint5to6"
    type="continuous">
    <origin
      xyz="0.162399999999994 0 0"
      rpy="0 0 0" />
    <parent
      link="link5" />
    <child
      link="link6" />
    <axis
      xyz="1 0 0" />
  </joint>
  <link
    name="link7">
    <inertial>
      <origin
        xyz="-4.94980884613305E-08 -0.0701300869037302 -6.31668961434475E-08"
        rpy="0 0 0" />
      <mass
        value="0.869909136744433" />
      <inertia
        ixx="0.00355831006646369"
        ixy="-3.18908705115779E-12"
        ixz="2.62810393495205E-10"
        iyy="0.0010013970608803"
        iyz="1.20370999840181E-10"
        izz="0.0034916422873186" />
    </inertial>
    <visual>
      <origin
        xyz="0 0 0"
        rpy="0 0 0" />
      <geometry>
        <mesh
          filename="package://robotarm/meshes/link7.STL" />
      </geometry>
      <material
        name="">
        <color
          rgba="0.792156862745098 0.819607843137255 0.933333333333333 1" />
      </material>
    </visual>
    <collision>
      <origin
        xyz="0 0 0"
        rpy="0 0 0" />
      <geometry>
        <mesh
          filename="package://robotarm/meshes/link7.STL" />
      </geometry>
    </collision>
  </link>
  <joint
    name="joint6to7"
    type="continuous">
    <origin
      xyz="0 0.112399999999999 0"
      rpy="0 0 0" />
    <parent
      link="link6" />
    <child
      link="link7" />
    <axis
      xyz="0 1 0" />
  </joint>
  <link
    name="link8">
    <inertial>
      <origin
        xyz="0.000716655966193719 4.44089209850063E-16 -1.31625749873033E-14"
        rpy="0 0 0" />
      <mass
        value="0.509047523656065" />
      <inertia
        ixx="0.000402319698175284"
        ixy="-9.86797783437605E-21"
        ixz="-5.52860385043055E-22"
        iyy="0.000620169294447699"
        iyz="1.27626649220071E-21"
        izz="0.000620258587978795" />
    </inertial>
    <visual>
      <origin
        xyz="0 0 0"
        rpy="0 0 0" />
      <geometry>
        <mesh
          filename="package://robotarm/meshes/link8.STL" />
      </geometry>
      <material
        name="">
        <color
          rgba="0.792156862745098 0.819607843137255 0.933333333333333 1" />
      </material>
    </visual>
    <collision>
      <origin
        xyz="0 0 0"
        rpy="0 0 0" />
      <geometry>
        <mesh
          filename="package://robotarm/meshes/link8.STL" />
      </geometry>
    </collision>
  </link>
  <joint
    name="joint7to8"
    type="continuous">
    <origin
      xyz="0 0 0"
      rpy="0 0 0" />
    <parent
      link="link7" />
    <child
      link="link8" />
    <axis
      xyz="1 0 0" />
  </joint>
  <link
    name="catcher_upper">
    <inertial>
      <origin
        xyz="0.067620295463843 -7.26885100552912E-15 -0.00145357344615116"
        rpy="0 0 0" />
      <mass
        value="0.11687084901057" />
      <inertia
        ixx="0.000178334647219039"
        ixy="-1.03113604510021E-18"
        ixz="4.12839829463047E-05"
        iyy="0.000176536090815463"
        iyz="-2.93953828418774E-18"
        izz="0.000298177215578335" />
    </inertial>
    <visual>
      <origin
        xyz="0 0 0"
        rpy="0 0 0" />
      <geometry>
        <mesh
          filename="package://robotarm/meshes/catcher_upper.STL" />
      </geometry>
      <material
        name="">
        <color
          rgba="0.792156862745098 0.819607843137255 0.933333333333333 1" />
      </material>
    </visual>
    <collision>
      <origin
        xyz="0 0 0"
        rpy="0 0 0" />
      <geometry>
        <mesh
          filename="package://robotarm/meshes/catcher_upper.STL" />
      </geometry>
    </collision>
  </link>
  <joint
    name="joint_upper"
    type="continuous">
    <origin
      xyz="0.05 0 0"
      rpy="-1.5707963267949 0 0" />
    <parent
      link="link8" />
    <child
      link="catcher_upper" />
    <axis
      xyz="0 1 0" />
  </joint>
  <link
    name="catcher_lower">
    <inertial>
      <origin
        xyz="0.0643967325741822 4.43960254547004E-15 -0.0101626910231036"
        rpy="0 0 0" />
      <mass
        value="0.0720761747561821" />
      <inertia
        ixx="2.58412062080603E-05"
        ixy="-3.87691241053914E-19"
        ixz="2.3935119770295E-05"
        iyy="9.4353591657348E-05"
        iyz="2.09230677007042E-19"
        izz="8.26408938511031E-05" />
    </inertial>
    <visual>
      <origin
        xyz="0 0 0"
        rpy="0 0 0" />
      <geometry>
        <mesh
          filename="package://robotarm/meshes/catcher_lower.STL" />
      </geometry>
      <material
        name="">
        <color
          rgba="0.792156862745098 0.819607843137255 0.933333333333333 1" />
      </material>
    </visual>
    <collision>
      <origin
        xyz="0 0 0"
        rpy="0 0 0" />
      <geometry>
        <mesh
          filename="package://robotarm/meshes/catcher_lower.STL" />
      </geometry>
    </collision>
  </link>
  <joint
    name="joint_lower"
    type="continuous">
    <origin
      xyz="0.0600000000000061 -0.00750000000000006 0"
      rpy="1.5707963267949 0 0" />
    <parent
      link="link8" />
    <child
      link="catcher_lower" />
    <axis
      xyz="0 1 0" />
  </joint>
</robot>